Workbook

Sheet Leia
A1: Nomes de técnica gerados: o jogo junta peça 1 + peça 2 + nome-base.
A2: Chinês: 仙 + 磐 + 灵水 (imortal + rocha maciça + água espiritual). Inglês: "Sloth's Solid Spiritual Water".
A3: Em PT o mod vai montar: nome-base + adjetivo (peça 2, concordando) + complemento (peça 1).
A4: Exemplo: "Água Espiritual" + "Sólida" + "do Imortal" = "Água Espiritual Sólida do Imortal".
A6: O que preencher (colunas amarelas):
A7: Peça 1: o complemento já com a preposição: "do Imortal", "da Lua", "do Dragão", "das Cinzas".
A8: Peça 2: o adjetivo no masculino singular e, se mudar, no feminino ("Sólido" / "Sólida").
A9: Feminino vazio = igual ao masculino ("Celeste", "Azul"). O plural o mod faz sozinho.
A10: Se a peça 2 for uma locução ("de Névoa"), ela não varia: pode escrever no masculino só.
A11: Nomes-base: gênero (m/f) e número (s/p) estão preenchidos por palpite; corrija os errados.
A13: Referência: "Sentido do hanzi" é o significado do caractere chinês. O inglês do jogo se perde da
A14: peça 1 nº 113 em diante (仙 "imortal" virou "Sloth's"); a coluna Obs. marca onde o inglês não bate.
... A18: Todas as combinações possíveis seriam 200 × 200 × ~700 nomes-base (milhões), por isso a planilha é por peça.

Sheet Peça 1
A1: ID | B1: Hanzi | C1: Sentido do hanzi | D1: Inglês do jogo | E1: Obs. | F1: Sua tradução (com "do/da/dos/das") | G1: Exemplo
A2: 1 | B2: 飞 | C2: voar | D2: Hoverer's | F2: do Voo | G2: =IF(F2="","","Técnica Sólida "&F2)
A3: 2 | B3: 舞 | C3: dançar | D3: Dancer's | F3: da Dança | G3: =IF(F3="","","Técnica Sólida "&F3)
A4: 3 | B4: 吹 | C4: soprar | D4: Blower's | F4: do Sopro | G4: =IF(F4="","","Técnica Sólida "&F4)
A5: 4 | B5: 落 | C5: cair | D5: Fallen's | F5: da Queda | G5: =IF(F5="","","Técnica Sólida "&F5)
A6: 5 | B6: 飘 | C6: esvoaçar, flutuar | D6: Drifter's | F6: da Brisa | G6: =IF(F6="","","Técnica Sólida "&F6)
A7: 6 | B7: 斩 | C7: decepar | D7: Cutter's | F7: da Degola | G7: =IF(F7="","","Técnica Sólida "&F7)
A8: 7 | B8: 断 | C8: romper, cortar | D8: Taken's | F8: da Ruptura | G8: =IF(F8="","","Técnica Sólida "&F8)
A9: 8 | B9: 凝 | C9: condensar | D9: Thinker's | F9: da Condensação | G9: =IF(F9="","","Técnica Sólida "&F9)
A10: 9 | B10: 破 | C10: quebrar, romper | D10: Ravager's | F10: da Quebra | G10: =IF(F10="","","Técnica Sólida "&F10)
A11: 10 | B11: 握 | C11: agarrar | D11: Holder's | F11: do Agarre | G11: =IF(F11="","","Técnica Sólida "&F11)
A12: 11 | B12: 撕 | C12: rasgar | D12: Slicer's | F12: do Rasgo | G12: =IF(F12="","","Técnica Sólida "&F12)
A13: 12 | B13: 聚 | C13: reunir | D13: Fixer's | F13: da Convergência | G13: =IF(F13="","","Técnica Sólida "&F13)
... A113: 112 | B113: 奔 | C113: correr, galopar | D113: Runner's | F113: da Corrida | G113: =IF(F113="","","Técnica Sólida "&F113)
A114: 113 | B114: 烈 | C114: feroz, intenso | D114: Carp's | E114: o inglês do jogo não segue o hanzi daqui em diante (lista desalinhada: pecados, virtudes etc.) | F114: da Ferocidade | G114: =IF(F114="","","Técnica Sólida "&F114)
A115: 114 | B115: 半 | C115: metade | D115: Wind's | E115: o inglês do jogo não segue o hanzi daqui em diante (lista desalinhada: pecados, virtudes etc.) | F115: da Metade | G115: =IF(F115="","","Técnica Sólida "&F115)
A116: 115 | B116: 重 | C116: pesado | D116: Earth's | E116: o inglês do jogo não segue o hanzi daqui em diante (lista desalinhada: pecados, virtudes etc.) | F116: do Peso | G116: =IF(F116="","","Técnica Sólida "&F116)
A117: 116 | B117: 太 | C117: supremo, grande | D117: Metal's | E117: o inglês do jogo não segue o hanzi daqui em diante (lista desalinhada: pecados, virtudes etc.) | F117: do Supremo | G117: =IF(F117="","","Técnica Sólida "&F117)
A118: 117 | B118: 弥 | C118: preencher, vasto | D118: Fire's | E118: o inglês do jogo não segue o hanzi daqui em diante (lista desalinhada: pecados, virtudes etc.) | F118: da Imensidão | G118: =IF(F118="","","Técnica Sólida "&F118)
A119: 118 | B119: 漫 | C119: transbordar, vasto | D119: Water's | E119: o inglês do jogo não segue o hanzi daqui em diante (lista desalinhada: pecados, virtudes etc.) | F119: do Transbordo | G119: =IF(F119="","","Técnica Sólida "&F119)
A120: 119 | B120: 诛 | C120: executar, punir | D120: Essence's | E120: o inglês do jogo não segue o hanzi daqui em diante (lista desalinhada: pecados, virtudes etc.) | F120: da Execução | G120: =IF(F120="","","Técnica Sólida "&F120)
A121: 120 | B121: 逆 | C121: inverso, contra a corrente | D121: Pearl's | E121: o inglês do jogo não segue o hanzi daqui em diante (lista desalinhada: pecados, virtudes etc.) | F121: do Inverso | G121: =IF(F121="","","Técnica Sólida "&F121)
A122: 121 | B122: 劈 | C122: fender (de cima a baixo) | D122: Wrath's | E122: o inglês do jogo não segue o hanzi daqui em diante (lista desalinhada: pecados, virtudes etc.) | F122: do Fendimento | G122: =IF(F122="","","Técnica Sólida "&F122)
A123: 122 | B123: 卷 | C123: enrolar, turbilhão | D123: Envy's | E123: o inglês do jogo não segue o hanzi daqui em diante (lista desalinhada: pecados, virtudes etc.) | F123: do Turbilhão | G123: =IF(F123="","","Técnica Sólida "&F123)
A124: 123 | B124: 荡 | C124: varrer, agitar | D124: Lust's | E124: o inglês do jogo não segue o hanzi daqui em diante (lista desalinhada: pecados, virtudes etc.) | F124: da Tormenta | G124: =IF(F124="","","Técnica Sólida "&F124)
A125: 124 | B125: 横 | C125: transversal, desenfreado | D125: Greed's | E125: o inglês do jogo não segue o hanzi daqui em diante (lista desalinhada: pecados, virtudes etc.) | F125: do Desenfreado | G125: =IF(F125="","","Técnica Sólida "&F125)
... A201: 200 | B201: 移 | C201: mover | D201: Memory's | E201: o inglês do jogo não segue o hanzi daqui em diante (lista desalinhada: pecados, virtudes etc.) | F201: do Movimento | G201: =IF(F201="","","Técnica Sólida "&F201)

Sheet Peça 2
A1: ID | B1: Hanzi | C1: Sentido do hanzi | D1: Inglês do jogo | E1: Obs. | F1: Masculino | G1: Feminino (se mudar) | H1: Exemplo masculino | I1: Exemplo feminino
A2: 201 | B2: 云 | C2: nuvem | D2: Clouded | F2: Nublado | G2: Nublada | H2: =IF(F2="","","Manual Secreto "&F2&" do Imortal") | I2: =IF(F2="","","Técnica "&IF(G2="",F2,G2)&" do Imortal")
A3: 202 | B3: 羽 | C3: pena, pluma | D3: Feathered | F3: Plumado | G3: Plumada | H3: =IF(F3="","","Manual Secreto "&F3&" do Imortal") | I3: =IF(F3="","","Técnica "&IF(G3="",F3,G3)&" do Imortal")
A4: 203 | B4: 雨 | C4: chuva | D4: Drowned | F4: Chuvoso | G4: Chuvosa | H4: =IF(F4="","","Manual Secreto "&F4&" do Imortal") | I4: =IF(F4="","","Técnica "&IF(G4="",F4,G4)&" do Imortal")
A5: 204 | B5: 雪 | C5: neve | D5: Frozen | F5: Nevado | G5: Nevada | H5: =IF(F5="","","Manual Secreto "&F5&" do Imortal") | I5: =IF(F5="","","Técnica "&IF(G5="",F5,G5)&" do Imortal")
A6: 205 | B6: 花 | C6: flor | D6: Petaled | F6: Florido | G6: Florida | H6: =IF(F6="","","Manual Secreto "&F6&" do Imortal") | I6: =IF(F6="","","Técnica "&IF(G6="",F6,G6)&" do Imortal")
A7: 206 | B7: 星 | C7: estrela | D7: Starry | F7: Estelar | H7: =IF(F7="","","Manual Secreto "&F7&" do Imortal") | I7: =IF(F7="","","Técnica "&IF(G7="",F7,G7)&" do Imortal")
A8: 207 | B8: 月 | C8: lua | D8: Moonlit | F8: Lunar | H8: =IF(F8="","","Manual Secreto "&F8&" do Imortal") | I8: =IF(F8="","","Técnica "&IF(G8="",F8,G8)&" do Imortal")
A9: 208 | B9: 天 | C9: céu | D9: Cerulean | F9: Celeste | H9: =IF(F9="","","Manual Secreto "&F9&" do Imortal") | I9: =IF(F9="","","Técnica "&IF(G9="",F9,G9)&" do Imortal")
A10: 209 | B10: 空 | C10: vazio | D10: Empty | F10: Vazio | G10: Vazia | H10: =IF(F10="","","Manual Secreto "&F10&" do Imortal") | I10: =IF(F10="","","Técnica "&IF(G10="",F10,G10)&" do Imortal")
A11: 210 | B11: 魂 | C11: alma | D11: Ensouled | F11: Anímico | G11: Anímica | H11: =IF(F11="","","Manual Secreto "&F11&" do Imortal") | I11: =IF(F11="","","Técnica "&IF(G11="",F11,G11)&" do Imortal")
A12: 211 | B12: 霜 | C12: geada | D12: Frosty | F12: Gélido | G12: Gélida | H12: =IF(F12="","","Manual Secreto "&F12&" do Imortal") | I12: =IF(F12="","","Técnica "&IF(G12="",F12,G12)&" do Imortal")
A13: 212 | B13: 神 | C13: divino | D13: Spirited | F13: Divino | G13: Divina | H13: =IF(F13="","","Manual Secreto "&F13&" do Imortal") | I13: =IF(F13="","","Técnica "&IF(G13="",F13,G13)&" do Imortal")
A14: 213 | B14: 元 | C14: primordial | D14: Original | F14: Primordial | H14: =IF(F14="","","Manual Secreto "&F14&" do Imortal") | I14: =IF(F14="","","Técnica "&IF(G14="",F14,G14)&" do Imortal")
A15: 214 | B15: 气 | C15: qi, ar | D15: Airy | F15: Eóleo | G15: Eólea | H15: =IF(F15="","","Manual Secreto "&F15&" do Imortal") | I15: =IF(F15="","","Técnica "&IF(G15="",F15,G15)&" do Imortal")
A16: 215 | B16: 日 | C16: sol, dia | D16: Sunny | F16: Solar | H16: =IF(F16="","","Manual Secreto "&F16&" do Imortal") | I16: =IF(F16="","","Técnica "&IF(G16="",F16,G16)&" do Imortal")
A17: 216 | B17: 仞 | C17: escarpa (medida antiga de altura) | D17: Edged | F17: Escarpado | G17: Escarpada | H17: =IF(F17="","","Manual Secreto "&F17&" do Imortal") | I17: =IF(F17="","","Técnica "&IF(G17="",F17,G17)&" do Imortal")
A18: 217 | B18: 冥 | C18: submundo, trevas | D18: Nether | F18: Abissal | H18: =IF(F18="","","Manual Secreto "&F18&" do Imortal") | I18: =IF(F18="","","Técnica "&IF(G18="",F18,G18)&" do Imortal")
A19: 218 | B19: 灵 | C19: espírito, éter | D19: Ethereal | F19: Espiritual | H19: =IF(F19="","","Manual Secreto "&F19&" do Imortal") | I19: =IF(F19="","","Técnica "&IF(G19="",F19,G19)&" do Imortal")
A20: 219 | B20: 影 | C20: sombra | D20: Shadowy | F20: Sombrio | G20: Sombria | H20: =IF(F20="","","Manual Secreto "&F20&" do Imortal") | I20: =IF(F20="","","Técnica "&IF(G20="",F20,G20)&" do Imortal")
A21: 220 | B21: 尘 | C21: poeira | D21: Dusted | F21: Cinéreo | G21: Cinérea | H21: =IF(F21="","","Manual Secreto "&F21&" do Imortal") | I21: =IF(F21="","","Técnica "&IF(G21="",F21,G21)&" do Imortal")
A22: 221 | B22: 音 | C22: som | D22: Chiming | F22: Sonoro | G22: Sonora | H22: =IF(F22="","","Manual Secreto "&F22&" do Imortal") | I22: =IF(F22="","","Técnica "&IF(G22="",F22,G22)&" do Imortal")
A23: 222 | B23: 阳 | C23: sol, yang | D23: Sunlit | F23: Radiante | H23: =IF(F23="","","Manual Secreto "&F23&" do Imortal") | I23: =IF(F23="","","Técnica "&IF(G23="",F23,G23)&" do Imortal")
A24: 223 | B24: 痕 | C24: cicatriz, marca | D24: Wounded | F24: Marcado | G24: Marcada | H24: =IF(F24="","","Manual Secreto "&F24&" do Imortal") | I24: =IF(F24="","","Técnica "&IF(G24="",F24,G24)&" do Imortal")
A25: 224 | B25: 龙 | C25: dragão | D25: Draconic | F25: Draconiano | G25: Draconiana | H25: =IF(F25="","","Manual Secreto "&F25&" do Imortal") | I25: =IF(F25="","","Técnica "&IF(G25="",F25,G25)&" do Imortal")
A26: 225 | B26: 血 | C26: sangue | D26: Blooded | F26: Sanguinário | G26: Sanguinária | H26: =IF(F26="","","Manual Secreto "&F26&" do Imortal") | I26: =IF(F26="","","Técnica "&IF(G26="",F26,G26)&" do Imortal")
A27: 226 | B27: 锋 | C27: gume | D27: Edgy | F27: Afiado | G27: Afiada | H27: =IF(F27="","","Manual Secreto "&F27&" do Imortal") | I27: =IF(F27="","","Técnica "&IF(G27="",F27,G27)&" do Imortal")
A28: 227 | B28: 心 | C28: coração | D28: Heartfelt | F28: Cordial | H28: =IF(F28="","","Manual Secreto "&F28&" do Imortal") | I28: =IF(F28="","","Técnica "&IF(G28="",F28,G28)&" do Imortal")
A29: 228 | B29: 山 | C29: montanha | D29: Hilly | F29: Montanhês | G29: Montanhesa | H29: =IF(F29="","","Manual Secreto "&F29&" do Imortal") | I29: =IF(F29="","","Técnica "&IF(G29="",F29,G29)&" do Imortal")
A30: 229 | B30: 阴 | C30: sombra, yin | D30: Dark | F30: Obscuro | G30: Obscura | H30: =IF(F30="","","Manual Secreto "&F30&" do Imortal") | I30: =IF(F30="","","Técnica "&IF(G30="",F30,G30)&" do Imortal")
A31: 230 | B31: 翼 | C31: asa | D31: Winged | F31: Alado | G31: Alada | H31: =IF(F31="","","Manual Secreto "&F31&" do Imortal") | I31: =IF(F31="","","Técnica "&IF(G31="",F31,G31)&" do Imortal")
A32: 231 | B32: 梦 | C32: sonho | D32: Dreamy | F32: Onírico | G32: Onírica | H32: =IF(F32="","","Manual Secreto "&F32&" do Imortal") | I32: =IF(F32="","","Técnica "&IF(G32="",F32,G32)&" do Imortal")
A33: 232 | B33: 光 | C33: luz | D33: Light | F33: Luminoso | G33: Luminosa | H33: =IF(F33="","","Manual Secreto "&F33&" do Imortal") | I33: =IF(F33="","","Técnica "&IF(G33="",F33,G33)&" do Imortal")
A34: 233 | B34: 莲 | C34: lótus | D34: Blooming | F34: Imaculado | G34: Imaculada | H34: =IF(F34="","","Manual Secreto "&F34&" do Imortal") | I34: =IF(F34="","","Técnica "&IF(G34="",F34,G34)&" do Imortal")
A35: 234 | B35: 域 | C35: domínio, reino | D35: Worldly | F35: Soberano | G35: Soberana | H35: =IF(F35="","","Manual Secreto "&F35&" do Imortal") | I35: =IF(F35="","","Técnica "&IF(G35="",F35,G35)&" do Imortal")
A36: 235 | B36: 魔 | C36: demônio | D36: Demonic | F36: Demoníaco | G36: Demoníaca | H36: =IF(F36="","","Manual Secreto "&F36&" do Imortal") | I36: =IF(F36="","","Técnica "&IF(G36="",F36,G36)&" do Imortal")
A37: 236 | B37: 鸦 | C37: corvo | D37: Cawing | F37: Corvino | G37: Corvina | H37: =IF(F37="","","Manual Secreto "&F37&" do Imortal") | I37: =IF(F37="","","Técnica "&IF(G37="",F37,G37)&" do Imortal")
A38: 237 | B38: 狱 | C38: prisão, inferno | D38: Binding | F38: Infernal | H38: =IF(F38="","","Manual Secreto "&F38&" do Imortal") | I38: =IF(F38="","","Técnica "&IF(G38="",F38,G38)&" do Imortal")
A39: 238 | B39: 邪 | C39: maligno | D39: Evil | F39: Maligno | G39: Maligna | H39: =IF(F39="","","Manual Secreto "&F39&" do Imortal") | I39: =IF(F39="","","Técnica "&IF(G39="",F39,G39)&" do Imortal")
A40: 239 | B40: 烟 | C40: fumaça | D40: Smoky | F40: Fumegante | H40: =IF(F40="","","Manual Secreto "&F40&" do Imortal") | I40: =IF(F40="","","Técnica "&IF(G40="",F40,G40)&" do Imortal")
...

Sheet Nomes-base
A1: Nome-base (já traduzido) | B1: Gênero (m/f) | C1: Número (s/p) | D1: Chinês | E1: Inglês | F1: Chave
A2: Movimentação | B2: f | C2: s | D2: 劲 | E2: Move | F2: ability_name_last1
A3: Sutra | B3: m | C3: s | D3: 经 | E3: Sutra | F3: ability_name_last2
A4: Técnica | B4: f | C4: s | D4: 式 | E4: Technique | F4: ability_name_last3
A5: Guia | B5: m | C5: s | D5: 诀 | E5: Guide | F5: ability_name_last4
A6: Compêndio | B6: m | C6: s | D6: 录 | E6: Compendium | F6: ability_name_last5
A7: Manual Secreto | B7: m | C7: s | D7: 秘卷 | E7: Secret Manual | F7: ability_name_last6
A8: Poder Divino | B8: m | C8: s | D8: 神功 | E8: Divine Power | F8: ability_name_last7
A9: Mestria | B9: f | C9: s | D9: 大法 | E9: Mastery | F9: ability_name_last8
A10: Salto | B10: m | C10: s | D10: 跃 | E10: Leap | F10: stepName1
A11: Ilusão | B11: f | C11: s | D11: 幻 | E11: Illusion | F11: stepName11
A12: Sombra | B12: f | C12: s | D12: 影 | E12: Shadow | F12: stepName12
... A21: Furtividade | B21: f | C21: s | D21: 隐 | E21: Stealth | F21: stepName6
A22: Pétalas caídas | B22: f | C22: p | D22: 落英 | F22: skill_name_middle10010
A23: Folhas de bordo caídas | B23: f | C23: p | D23: 落枫 | F23: skill_name_middle10020
A24: Ganso Caído | B24: m | C24: s | D24: 落雁 | F24: skill_name_middle10030
A25: Pôr do sol | B25: m | C25: s | D25: 落霞 | F25: skill_name_middle10040
A26: Dispersão Distante | B26: f | C26: s | D26: 开枝散叶 | E26: Spread Afar | F26: skill_name_middle100721
A27: Folhas e Pétalas | B27: f | C27: p | D27: 摘叶飞花 | E27: Leaves and Petals | F27: skill_name_middle1007212
A28: Broto de Bambu | B28: m | C28: s | D28: 春笋新芽 | E28: Bamboo Shoot | F28: skill_name_middle100724
A29: Proteção da Terra | B29: f | C29: s | D29: 大地守护 | E29: Earth's Guarding | F29: skill_name_middle100727
A30: Vento furioso | B30: m | C30: s | D30: 怒风 | F30: skill_name_middle10120
A31: Tempestade | B31: f | C31: s | D31: 暴风 | F31: skill_name_middle10130
A32: Seis vezes | B32: m | C32: p | D32: 六迴 | F32: skill_name_middle10210
A33: Oito vezes | B33: m | C33: s | D33: 八迴 | F33: skill_name_middle10220
A34: Dez vezes | B34: f | C34: s | D34: 十迴 | F34: skill_name_middle10230
A35: Dragão de Fogo | B35: m | C35: s | D35: 火龙 | F35: skill_name_middle10310
A36: Dragão de Chamas | B36: m | C36: s | D36: 焰龙 | F36: skill_name_middle10320
A37: Dragão da Vela | B37: m | C37: s | D37: 烛龙 | F37: skill_name_middle10330
A38: Dragão de Gelo | B38: m | C38: s | D38: 冰龙 | F38: skill_name_middle10410
A39: Dragão Gélido | B39: m | C39: s | D39: 凛龙 | F39: skill_name_middle10420
A40: Dragão Frio | B40: m | C40: s | D40: 寒龙 | F40: skill_name_middle10430
A41: Dragão da Geada | B41: m | C41: s | D41: 霜龙 | F41: skill_name_middle10440
... A59: Quebrando limites | B59: m | C59: s | D59: 破界 | F59: skill_name_middle10940
A60: Vento de Ossos | B60: m | C60: s | D60: 蚀骨阴风 | E60: Bone Etching Wind | F60: skill_name_middle110021
A61: Queda de Pedras | B61: f | C61: s | D61: 落石击 | E61: Stone Fall | F61: skill_name_middle110022
A62: Chama de Raposa | B62: f | C62: s | D62: 狐灵青炎 | E62: Fox Flame | F62: skill_name_middle110031
A63: Encanto | B63: m | C63: s | D63: 魅惑妖术 | E63: Enchant | F63: skill_name_middle110032
A64: Necromancia de Raposa | B64: f | C64: s | D64: 万狐通灵 | E64: Fox Necromancy | F64: skill_name_middle110033
A65: Beijo Maligno | B65: m | C65: s | D65: 致命飞吻 | E65: Evil Kiss | F65: skill_name_middle110036
...

Sheet Combinações
A1: Como fica no jogo | B1: Hanzi | C1: Inglês do jogo | D1: Peça 1 | E1: Peça 2 | F1: Nome-base | G1: aux: peça 1 | H1: aux: adjetivo | I1: aux: adjetivo concordado
A2: =IF(OR(G2="",I2=""),"(falta traduzir)",F2&" "&I2&" "&G2) | B2: 仙磐水灵术 | C2: Sloth's Solid Água Espiritual | D2: 127 | E2: 369 | F2: Água Espiritual | G2: =INDEX('Peça 1'!F:F,MATCH(D2,'Peça 1'!A:A,0))&"" | H2: =IF(AND(INDEX('Nomes-base'!B:B,MATCH(F2,'Nomes-base'!A:A,0))="f",INDEX('Peça 2'!G:G,MATCH(E2,'Peça 2'!A:A,0))&""<>""),INDEX('Peça 2'!G:G,MATCH(E2,'Peça 2'!A:A,0))&"",INDEX('Peça 2'!F:F,MATCH(E2,'Peça 2'!A:A,0))&"") | I2: =IF(OR(H2="",ISNUMBER(SEARCH(" ",H2)),INDEX('Nomes-base'!C:C,MATCH(F2,'Nomes-base'!A:A,0))<>"p"),H2,IF(RIGHT(H2,1)="s",H2,IF(RIGHT(H2,1)="l",LEFT(H2,LEN(H2)-1)&"is",IF(OR(RIGHT(H2,1)="r",RIGHT(H2,1)="z"),H2&"es",IF(RIGHT(H2,1)="m",LEFT(H2,LEN(H2)-1)&"ns",H2&"s")))))
A3: =IF(OR(G3="",I3=""),"(falta traduzir)",F3&" "&I3&" "&G3) | B3: 嗜落影 | C3: Sacrifice's Diving Sombra | D3: 140 | E3: 265 | F3: Sombra | G3: =INDEX('Peça 1'!F:F,MATCH(D3,'Peça 1'!A:A,0))&"" | H3: =IF(AND(INDEX('Nomes-base'!B:B,MATCH(F3,'Nomes-base'!A:A,0))="f",INDEX('Peça 2'!G:G,MATCH(E3,'Peça 2'!A:A,0))&""<>""),INDEX('Peça 2'!G:G,MATCH(E3,'Peça 2'!A:A,0))&"",INDEX('Peça 2'!F:F,MATCH(E3,'Peça 2'!A:A,0))&"") | I3: =IF(OR(H3="",ISNUMBER(SEARCH(" ",H3)),INDEX('Nomes-base'!C:C,MATCH(F3,'Nomes-base'!A:A,0))<>"p"),H3,IF(RIGHT(H3,1)="s",H3,IF(RIGHT(H3,1)="l",LEFT(H3,LEN(H3)-1)&"is",IF(OR(RIGHT(H3,1)="r",RIGHT(H3,1)="z"),H3&"es",IF(RIGHT(H3,1)="m",LEFT(H3,LEN(H3)-1)&"ns",H3&"s")))))
A4: =IF(OR(G4="",I4=""),"(falta traduzir)",F4&" "&I4&" "&G4) | B4: 青雾冰刺术 | C4: Cobalt's Misty Pingente de Gelo | D4: 49 | E4: 281 | F4: Pingente de Gelo | G4: =INDEX('Peça 1'!F:F,MATCH(D4,'Peça 1'!A:A,0))&"" | H4: =IF(AND(INDEX('Nomes-base'!B:B,MATCH(F4,'Nomes-base'!A:A,0))="f",INDEX('Peça 2'!G:G,MATCH(E4,'Peça 2'!A:A,0))&""<>""),INDEX('Peça 2'!G:G,MATCH(E4,'Peça 2'!A:A,0))&"",INDEX('Peça 2'!F:F,MATCH(E4,'Peça 2'!A:A,0))&"") | I4: =IF(OR(H4="",ISNUMBER(SEARCH(" ",H4)),INDEX('Nomes-base'!C:C,MATCH(F4,'Nomes-base'!A:A,0))<>"p"),H4,IF(RIGHT(H4,1)="s",H4,IF(RIGHT(H4,1)="l",LEFT(H4,LEN(H4)-1)&"is",IF(OR(RIGHT(H4,1)="r",RIGHT(H4,1)="z"),H4&"es",IF(RIGHT(H4,1)="m",LEFT(H4,LEN(H4)-1)&"ns",H4&"s")))))
A5: =IF(OR(G5="",I5=""),"(falta traduzir)",F5&" "&I5&" "&G5) | B5: 一落冰天眼 | C5: Wafter's Diving Olhar Gélido Celestial | D5: 167 | E5: 265 | F5: Olhar Gélido Celestial | G5: =INDEX('Peça 1'!F:F,MATCH(D5,'Peça 1'!A:A,0))&"" | H5: =IF(AND(INDEX('Nomes-base'!B:B,MATCH(F5,'Nomes-base'!A:A,0))="f",INDEX('Peça 2'!G:G,MATCH(E5,'Peça 2'!A:A,0))&""<>""),INDEX('Peça 2'!G:G,MATCH(E5,'Peça 2'!A:A,0))&"",INDEX('Peça 2'!F:F,MATCH(E5,'Peça 2'!A:A,0))&"") | I5: =IF(OR(H5="",ISNUMBER(SEARCH(" ",H5)),INDEX('Nomes-base'!C:C,MATCH(F5,'Nomes-base'!A:A,0))<>"p"),H5,IF(RIGHT(H5,1)="s",H5,IF(RIGHT(H5,1)="l",LEFT(H5,LEN(H5)-1)&"is",IF(OR(RIGHT(H5,1)="r",RIGHT(H5,1)="z"),H5&"es",IF(RIGHT(H5,1)="m",LEFT(H5,LEN(H5)-1)&"ns",H5&"s")))))
A6: =IF(OR(G6="",I6=""),"(falta traduzir)",F6&" "&I6&" "&G6) | B6: 惊鼎经 | C6: Fear's Vesseled Sutra | D6: 106 | E6: 305 | F6: Sutra | G6: =INDEX('Peça 1'!F:F,MATCH(D6,'Peça 1'!A:A,0))&"" | H6: =IF(AND(INDEX('Nomes-base'!B:B,MATCH(F6,'Nomes-base'!A:A,0))="f",INDEX('Peça 2'!G:G,MATCH(E6,'Peça 2'!A:A,0))&""<>""),INDEX('Peça 2'!G:G,MATCH(E6,'Peça 2'!A:A,0))&"",INDEX('Peça 2'!F:F,MATCH(E6,'Peça 2'!A:A,0))&"") | I6: =IF(OR(H6="",ISNUMBER(SEARCH(" ",H6)),INDEX('Nomes-base'!C:C,MATCH(F6,'Nomes-base'!A:A,0))<>"p"),H6,IF(RIGHT(H6,1)="s",H6,IF(RIGHT(H6,1)="l",LEFT(H6,LEN(H6)-1)&"is",IF(OR(RIGHT(H6,1)="r",RIGHT(H6,1)="z"),H6&"es",IF(RIGHT(H6,1)="m",LEFT(H6,LEN(H6)-1)&"ns",H6&"s")))))
A7: =IF(OR(G7="",I7=""),"(falta traduzir)",F7&" "&I7&" "&G7) | B7: 白血劲 | C7: Washer's Blooded Movimentação | D7: 92 | E7: 225 | F7: Movimentação | G7: =INDEX('Peça 1'!F:F,MATCH(D7,'Peça 1'!A:A,0))&"" | H7: =IF(AND(INDEX('Nomes-base'!B:B,MATCH(F7,'Nomes-base'!A:A,0))="f",INDEX('Peça 2'!G:G,MATCH(E7,'Peça 2'!A:A,0))&""<>""),INDEX('Peça 2'!G:G,MATCH(E7,'Peça 2'!A:A,0))&"",INDEX('Peça 2'!F:F,MATCH(E7,'Peça 2'!A:A,0))&"") | I7: =IF(OR(H7="",ISNUMBER(SEARCH(" ",H7)),INDEX('Nomes-base'!C:C,MATCH(F7,'Nomes-base'!A:A,0))<>"p"),H7,IF(RIGHT(H7,1)="s",H7,IF(RIGHT(H7,1)="l",LEFT(H7,LEN(H7)-1)&"is",IF(OR(RIGHT(H7,1)="r",RIGHT(H7,1)="z"),H7&"es",IF(RIGHT(H7,1)="m",LEFT(H7,LEN(H7)-1)&"ns",H7&"s")))))
A8: =IF(OR(G8="",I8=""),"(falta traduzir)",F8&" "&I8&" "&G8) | B8: 飞战式 | C8: Hoverer's Warring Técnica | D8: 1 | E8: 345 | F8: Técnica | G8: =INDEX('Peça 1'!F:F,MATCH(D8,'Peça 1'!A:A,0))&"" | H8: =IF(AND(INDEX('Nomes-base'!B:B,MATCH(F8,'Nomes-base'!A:A,0))="f",INDEX('Peça 2'!G:G,MATCH(E8,'Peça 2'!A:A,0))&""<>""),INDEX('Peça 2'!G:G,MATCH(E8,'Peça 2'!A:A,0))&"",INDEX('Peça 2'!F:F,MATCH(E8,'Peça 2'!A:A,0))&"") | I8: =IF(OR(H8="",ISNUMBER(SEARCH(" ",H8)),INDEX('Nomes-base'!C:C,MATCH(F8,'Nomes-base'!A:A,0))<>"p"),H8,IF(RIGHT(H8,1)="s",H8,IF(RIGHT(H8,1)="l",LEFT(H8,LEN(H8)-1)&"is",IF(OR(RIGHT(H8,1)="r",RIGHT(H8,1)="z"),H8&"es",IF(RIGHT(H8,1)="m",LEFT(H8,LEN(H8)-1)&"ns",H8&"s")))))
A9: =IF(OR(G9="",I9=""),"(falta traduzir)",F9&" "&I9&" "&G9) | B9: 御鸿诀 | C9: Wielder's Cardinal Guia | D9: 65 | E9: 393 | F9: Guia | G9: =INDEX('Peça 1'!F:F,MATCH(D9,'Peça 1'!A:A,0))&"" | H9: =IF(AND(INDEX('Nomes-base'!B:B,MATCH(F9,'Nomes-base'!A:A,0))="f",INDEX('Peça 2'!G:G,MATCH(E9,'Peça 2'!A:A,0))&""<>""),INDEX('Peça 2'!G:G,MATCH(E9,'Peça 2'!A:A,0))&"",INDEX('Peça 2'!F:F,MATCH(E9,'Peça 2'!A:A,0))&"") | I9: =IF(OR(H9="",ISNUMBER(SEARCH(" ",H9)),INDEX('Nomes-base'!C:C,MATCH(F9,'Nomes-base'!A:A,0))<>"p"),H9,IF(RIGHT(H9,1)="s",H9,IF(RIGHT(H9,1)="l",LEFT(H9,LEN(H9)-1)&"is",IF(OR(RIGHT(H9,1)="r",RIGHT(H9,1)="z"),H9&"es",IF(RIGHT(H9,1)="m",LEFT(H9,LEN(H9)-1)&"ns",H9&"s")))))
A10: =IF(OR(G10="",I10=""),"(falta traduzir)",F10&" "&I10&" "&G10) | B10: 六磐录 | C10: Integrity's Solid Compêndio | D10: 149 | E10: 369 | F10: Compêndio | G10: =INDEX('Peça 1'!F:F,MATCH(D10,'Peça 1'!A:A,0))&"" | H10: =IF(AND(INDEX('Nomes-base'!B:B,MATCH(F10,'Nomes-base'!A:A,0))="f",INDEX('Peça 2'!G:G,MATCH(E10,'Peça 2'!A:A,0))&""<>""),INDEX('Peça 2'!G:G,MATCH(E10,'Peça 2'!A:A,0))&"",INDEX('Peça 2'!F:F,MATCH(E10,'Peça 2'!A:A,0))&"") | I10: =IF(OR(H10="",ISNUMBER(SEARCH(" ",H10)),INDEX('Nomes-base'!C:C,MATCH(F10,'Nomes-base'!A:A,0))<>"p"),H10,IF(RIGHT(H10,1)="s",H10,IF(RIGHT(H10,1)="l",LEFT(H10,LEN(H10)-1)&"is",IF(OR(RIGHT(H10,1)="r",RIGHT(H10,1)="z"),H10&"es",IF(RIGHT(H10,1)="m",LEFT(H10,LEN(H10)-1)&"ns",H10&"s")))))
A11: =IF(OR(G11="",I11=""),"(falta traduzir)",F11&" "&I11&" "&G11) | B11: 遮战秘卷 | C11: Blocker's Warring Manual Secreto | D11: 108 | E11: 345 | F11: Manual Secreto | G11: =INDEX('Peça 1'!F:F,MATCH(D11,'Peça 1'!A:A,0))&"" | H11: =IF(AND(INDEX('Nomes-base'!B:B,MATCH(F11,'Nomes-base'!A:A,0))="f",INDEX('Peça 2'!G:G,MATCH(E11,'Peça 2'!A:A,0))&""<>""),INDEX('Peça 2'!G:G,MATCH(E11,'Peça 2'!A:A,0))&"",INDEX('Peça 2'!F:F,MATCH(E11,'Peça 2'!A:A,0))&"") | I11: =IF(OR(H11="",ISNUMBER(SEARCH(" ",H11)),INDEX('Nomes-base'!C:C,MATCH(F11,'Nomes-base'!A:A,0))<>"p"),H11,IF(RIGHT(H11,1)="s",H11,IF(RIGHT(H11,1)="l",LEFT(H11,LEN(H11)-1)&"is",IF(OR(RIGHT(H11,1)="r",RIGHT(H11,1)="z"),H11&"es",IF(RIGHT(H11,1)="m",LEFT(H11,LEN(H11)-1)&"ns",H11&"s")))))
A12: =IF(OR(G12="",I12=""),"(falta traduzir)",F12&" "&I12&" "&G12) | B12: 赤封式 | C12: Gore's Signing Técnica | D12: 50 | E12: 337 | F12: Técnica | G12: =INDEX('Peça 1'!F:F,MATCH(D12,'Peça 1'!A:A,0))&"" | H12: =IF(AND(INDEX('Nomes-base'!B:B,MATCH(F12,'Nomes-base'!A:A,0))="f",INDEX('Peça 2'!G:G,MATCH(E12,'Peça 2'!A:A,0))&""<>""),INDEX('Peça 2'!G:G,MATCH(E12,'Peça 2'!A:A,0))&"",INDEX('Peça 2'!F:F,MATCH(E12,'Peça 2'!A:A,0))&"") | I12: =IF(OR(H12="",ISNUMBER(SEARCH(" ",H12)),INDEX('Nomes-base'!C:C,MATCH(F12,'Nomes-base'!A:A,0))<>"p"),H12,IF(RIGHT(H12,1)="s",H12,IF(RIGHT(H12,1)="l",LEFT(H12,LEN(H12)-1)&"is",IF(OR(RIGHT(H12,1)="r",RIGHT(H12,1)="z"),H12&"es",IF(RIGHT(H12,1)="m",LEFT(H12,LEN(H12)-1)&"ns",H12&"s")))))
A13: =IF(OR(G13="",I13=""),"(falta traduzir)",F13&" "&I13&" "&G13) | B13: 正瑕式 | C13: Chao's Flawed Técnica | D13: 183 | E13: 273 | F13: Técnica | G13: =INDEX('Peça 1'!F:F,MATCH(D13,'Peça 1'!A:A,0))&"" | H13: =IF(AND(INDEX('Nomes-base'!B:B,MATCH(F13,'Nomes-base'!A:A,0))="f",INDEX('Peça 2'!G:G,MATCH(E13,'Peça 2'!A:A,0))&""<>""),INDEX('Peça 2'!G:G,MATCH(E13,'Peça 2'!A:A,0))&"",INDEX('Peça 2'!F:F,MATCH(E13,'Peça 2'!A:A,0))&"") | I13: =IF(OR(H13="",ISNUMBER(SEARCH(" ",H13)),INDEX('Nomes-base'!C:C,MATCH(F13,'Nomes-base'!A:A,0))<>"p"),H13,IF(RIGHT(H13,1)="s",H13,IF(RIGHT(H13,1)="l",LEFT(H13,LEN(H13)-1)&"is",IF(OR(RIGHT(H13,1)="r",RIGHT(H13,1)="z"),H13&"es",IF(RIGHT(H13,1)="m",LEFT(H13,LEN(H13)-1)&"ns",H13&"s")))))
... A234: =IF(OR(G234="",I234=""),"(falta traduzir)",F234&" "&I234&" "&G234) | B234: 移相怒血斩 | C234: Memory's Aspected Furyblood Cleave | D234: 200 | E234: 328 | F234: Corte do Sangue Furioso | G234: =INDEX('Peça 1'!F:F,MATCH(D234,'Peça 1'!A:A,0))&"" | H234: =IF(AND(INDEX('Nomes-base'!B:B,MATCH(F234,'Nomes-base'!A:A,0))="f",INDEX('Peça 2'!G:G,MATCH(E234,'Peça 2'!A:A,0))&""<>""),INDEX('Peça 2'!G:G,MATCH(E234,'Peça 2'!A:A,0))&"",INDEX('Peça 2'!F:F,MATCH(E234,'Peça 2'!A:A,0))&"") | I234: =IF(OR(H234="",ISNUMBER(SEARCH(" ",H234)),INDEX('Nomes-base'!C:C,MATCH(F234,'Nomes-base'!A:A,0))<>"p"),H234,IF(RIGHT(H234,1)="s",H234,IF(RIGHT(H234,1)="l",LEFT(H234,LEN(H234)-1)&"is",IF(OR(RIGHT(H234,1)="r",RIGHT(H234,1)="z"),H234&"es",IF(RIGHT(H234,1)="m",LEFT(H234,LEN(H234)-1)&"ns",H234&"s")))))
